<?xml version="1.0" encoding="UTF-8"?>
<testng-results skipped="0" failed="1" ignored="3" retried="1" total="5" passed="0">
  <reporter-output>
  </reporter-output>
  <suite name="Suite" duration-ms="34120" started-at="2022-11-14T22:10:57 EST" finished-at="2022-11-14T22:11:31 EST">
    <groups>
      <group name="ErrorHandling">
        <method signature="ErrorValidationsTest.LoginErrorValidation()[pri:0, instance:company.tests.ErrorValidationsTest@4f51b3e0]" name="LoginErrorValidation" class="company.tests.ErrorValidationsTest"/>
      </group> <!-- ErrorHandling -->
    </groups>
    <test name="Submit Order Test" duration-ms="12" started-at="2022-11-14T22:10:57 EST" finished-at="2022-11-14T22:10:57 EST">
    </test> <!-- Submit Order Test -->
    <test name="Error Validations Test" duration-ms="34120" started-at="2022-11-14T22:10:57 EST" finished-at="2022-11-14T22:11:31 EST">
      <class name="company.tests.ErrorValidationsTest">
        <test-method status="PASS" signature="launchApplication()[pri:0, instance:company.tests.ErrorValidationsTest@4f51b3e0]" name="launchApplication" is-config="true" duration-ms="9753" started-at="2022-11-14T22:10:57 EST" finished-at="2022-11-14T22:11:07 EST">
          <reporter-output>
          </reporter-output>
        </test-method> <!-- launchApplication -->
        <test-method status="SKIP" signature="LoginErrorValidation()[pri:0, instance:company.tests.ErrorValidationsTest@4f51b3e0]" name="LoginErrorValidation" duration-ms="1316" retried="true" started-at="2022-11-14T22:11:07 EST" finished-at="2022-11-14T22:11:08 EST">
          <exception class="java.lang.AssertionError">
            <message>
              <![CDATA[expected [Incorrect email or password.] but found [Incorrect email password.]]]>
            </message>
            <full-stacktrace>
              <![CDATA[java.lang.AssertionError: expected [Incorrect email or password.] but found [Incorrect email password.]
at org.testng.Assert.fail(Assert.java:99)
at org.testng.Assert.failNotEquals(Assert.java:1037)
at org.testng.Assert.assertEqualsImpl(Assert.java:140)
at org.testng.Assert.assertEquals(Assert.java:122)
at org.testng.Assert.assertEquals(Assert.java:629)
at org.testng.Assert.assertEquals(Assert.java:639)
at company.tests.ErrorValidationsTest.LoginErrorValidation(ErrorValidationsTest.java:30)
at sun.reflect.NativeMethodAccessorImpl.invoke0(Native Method)
at sun.reflect.NativeMethodAccessorImpl.invoke(Unknown Source)
at sun.reflect.DelegatingMethodAccessorImpl.invoke(Unknown Source)
at java.lang.reflect.Method.invoke(Unknown Source)
at org.testng.internal.MethodInvocationHelper.invokeMethod(MethodInvocationHelper.java:133)
at org.testng.internal.TestInvoker.invokeMethod(TestInvoker.java:598)
at org.testng.internal.TestInvoker.invokeTestMethod(TestInvoker.java:173)
at org.testng.internal.MethodRunner.runInSequence(MethodRunner.java:46)
at org.testng.internal.TestInvoker$MethodInvocationAgent.invoke(TestInvoker.java:824)
at org.testng.internal.TestInvoker.invokeTestMethods(TestInvoker.java:146)
at org.testng.internal.TestMethodWorker.invokeTestMethods(TestMethodWorker.java:146)
at org.testng.internal.TestMethodWorker.run(TestMethodWorker.java:128)
at java.util.ArrayList.forEach(Unknown Source)
at org.testng.TestRunner.privateRun(TestRunner.java:794)
at org.testng.TestRunner.run(TestRunner.java:596)
at org.testng.SuiteRunner.runTest(SuiteRunner.java:377)
at org.testng.SuiteRunner.access$000(SuiteRunner.java:28)
at org.testng.SuiteRunner$SuiteWorker.run(SuiteRunner.java:418)
at org.testng.internal.thread.ThreadUtil.lambda$execute$0(ThreadUtil.java:64)
at java.util.concurrent.FutureTask.run(Unknown Source)
at java.util.concurrent.ThreadPoolExecutor.runWorker(Unknown Source)
at java.util.concurrent.ThreadPoolExecutor$Worker.run(Unknown Source)
at java.lang.Thread.run(Unknown Source)
]]>
            </full-stacktrace>
          </exception> <!-- java.lang.AssertionError -->
          <reporter-output>
          </reporter-output>
        </test-method> <!-- LoginErrorValidation -->
        <test-method status="PASS" signature="tearDown()[pri:0, instance:company.tests.ErrorValidationsTest@4f51b3e0]" name="tearDown" is-config="true" duration-ms="16249" started-at="2022-11-14T22:11:08 EST" finished-at="2022-11-14T22:11:25 EST">
          <reporter-output>
          </reporter-output>
        </test-method> <!-- tearDown -->
        <test-method status="PASS" signature="launchApplication()[pri:0, instance:company.tests.ErrorValidationsTest@4f51b3e0]" name="launchApplication" is-config="true" duration-ms="5482" started-at="2022-11-14T22:11:25 EST" finished-at="2022-11-14T22:11:30 EST">
          <reporter-output>
          </reporter-output>
        </test-method> <!-- launchApplication -->
        <test-method status="FAIL" signature="LoginErrorValidation()[pri:0, instance:company.tests.ErrorValidationsTest@4f51b3e0]" name="LoginErrorValidation" duration-ms="1202" started-at="2022-11-14T22:11:30 EST" finished-at="2022-11-14T22:11:31 EST">
          <exception class="java.lang.AssertionError">
            <message>
              <![CDATA[expected [Incorrect email or password.] but found [Incorrect email password.]]]>
            </message>
            <full-stacktrace>
              <![CDATA[java.lang.AssertionError: expected [Incorrect email or password.] but found [Incorrect email password.]
at org.testng.Assert.fail(Assert.java:99)
at org.testng.Assert.failNotEquals(Assert.java:1037)
at org.testng.Assert.assertEqualsImpl(Assert.java:140)
at org.testng.Assert.assertEquals(Assert.java:122)
at org.testng.Assert.assertEquals(Assert.java:629)
at org.testng.Assert.assertEquals(Assert.java:639)
at company.tests.ErrorValidationsTest.LoginErrorValidation(ErrorValidationsTest.java:30)
at sun.reflect.NativeMethodAccessorImpl.invoke0(Native Method)
at sun.reflect.NativeMethodAccessorImpl.invoke(Unknown Source)
at sun.reflect.DelegatingMethodAccessorImpl.invoke(Unknown Source)
at java.lang.reflect.Method.invoke(Unknown Source)
at org.testng.internal.MethodInvocationHelper.invokeMethod(MethodInvocationHelper.java:133)
at org.testng.internal.TestInvoker.invokeMethod(TestInvoker.java:598)
at org.testng.internal.TestInvoker.retryFailed(TestInvoker.java:213)
at org.testng.internal.MethodRunner.runInSequence(MethodRunner.java:58)
at org.testng.internal.TestInvoker$MethodInvocationAgent.invoke(TestInvoker.java:824)
at org.testng.internal.TestInvoker.invokeTestMethods(TestInvoker.java:146)
at org.testng.internal.TestMethodWorker.invokeTestMethods(TestMethodWorker.java:146)
at org.testng.internal.TestMethodWorker.run(TestMethodWorker.java:128)
at java.util.ArrayList.forEach(Unknown Source)
at org.testng.TestRunner.privateRun(TestRunner.java:794)
at org.testng.TestRunner.run(TestRunner.java:596)
at org.testng.SuiteRunner.runTest(SuiteRunner.java:377)
at org.testng.SuiteRunner.access$000(SuiteRunner.java:28)
at org.testng.SuiteRunner$SuiteWorker.run(SuiteRunner.java:418)
at org.testng.internal.thread.ThreadUtil.lambda$execute$0(ThreadUtil.java:64)
at java.util.concurrent.FutureTask.run(Unknown Source)
at java.util.concurrent.ThreadPoolExecutor.runWorker(Unknown Source)
at java.util.concurrent.ThreadPoolExecutor$Worker.run(Unknown Source)
at java.lang.Thread.run(Unknown Source)
]]>
            </full-stacktrace>
          </exception> <!-- java.lang.AssertionError -->
          <reporter-output>
          </reporter-output>
        </test-method> <!-- LoginErrorValidation -->
        <test-method status="PASS" signature="tearDown()[pri:0, instance:company.tests.ErrorValidationsTest@4f51b3e0]" name="tearDown" is-config="true" duration-ms="65" started-at="2022-11-14T22:11:31 EST" finished-at="2022-11-14T22:11:31 EST">
          <reporter-output>
          </reporter-output>
        </test-method> <!-- tearDown -->
      </class> <!-- company.tests.ErrorValidationsTest -->
    </test> <!-- Error Validations Test -->
  </suite> <!-- Suite -->
</testng-results>
